Workbook

Sheet 2009
A1: 2009 | B1: David | C1: Carlos | D1: Laura | E1: Jorge | F1: Sergio | G1: Poli | H1: Nuria | I1: Sara | J1: Dario | K1: Pedro | L1: Inés | M1: Chema | N1: Maite | O1: Abuelos
A2: Tiro con pistola de agua | B2: PLATA | E2: ORO | F2: PLATA
A3: -1 | B3: ORO | C3: BRONCE | E3: PLATA
A4: Fútbol | B4: ORO | C4: PLATA | E4: ORO | F4: PLATA | G4: ORO
A5: Carrera | C5: BRONCE | E5: PLATA | F5: ORO
A6: C. Catán-1 | B6: PLATA | F6: PLATA | G6: BRONCE | L6: ORO
A7: Béisbol | B7: ORO | C7: PLATA | D7: ORO | E7: PLATA | F7: ORO | I7: PLATA
A8: Comba | B8: BRONCE | D8: PLATA | G8: ORO
A9: Frontón | B9: ORO | C9: PLATA | E9: BRONCE
A10: Carrera bicis | B10: PLATA | C10: ORO | G10: BRONCE
A11: Sillas | E11: PLATA | F11: ORO | H11: BRONCE
A12: Tirachinas | E12: BRONCE | F12: ORO | I12: BRONCE
A13: Petanca | C13: BRONCE | D13: PLATA | E13: BRONCE | F13: ORO | H13: PLATA
A14: Natación | B14: ORO | C14: ORO | E14: PLATA | F14: BRONCE
A15: Natación | B15: ORO | C15: PLATA | E15: PLATA | F15: BRONCE
A16: Natación | B16: ORO | C16: PLATA | E16: BRONCE
A17: Natación | B17: ORO | C17: BRONCE
A18: Baloncesto | B18: ORO | C18: PLATA | D18: PLATA | E18: BRONCE | F18: ORO | G18: ORO
A19: C.Catán-2 | B19: PLATA | C19: ORO | F19: PLATA | G19: BRONCE
A20: Dardos | B20: ORO | D20: PLATA | F20: BRONCE
A21: Dardos | B21: PLATA | C21: ORO | E21: BRONCE
A22: Petanca | B22: ORO | F22: BRONCE | H22: PLATA | J22: ORO
A23: Bicis | D23: PLATA | F23: PLATA
A24: Burro | B24: ORO | D24: PLATA | E24: BRONCE
A25: Lanzamiento de disco | D25: BRONCE | E25: PLATA | F25: ORO | H25: ORO | I25: ORO
A26: Cricket | B26: BRONCE | D26: ORO | E26: PLATA
A27: Dardos | B27: BRONCE | E27: ORO | G27: PLATA
A28: Dardos | B28: PLATA | E28: ORO | F28: BRONCE
A29: Burro | B29: PLATA | D29: ORO | F29: BRONCE
A30: Fórmula 1 | I30: ORO
A31: Romp… | D31: ORO | E31: ORO | F31: PLATA | O31: ORO
A32: Pañuelo | C32: PLATA | D32: ORO | E32: ORO | F32: PLATA | G32: ORO | H32: ORO | I32: PLATA | J32: ORO | L32: PLATA
A33: Relevos | B33: ORO | C33: ORO | E33: PLATA | F33: PLATA
A34: C.Catán 3º | B34: PLATA | C34: BRONCE | F34: PLATA | G34: ORO | L34: BRONCE
A35: Cinquillo | C35: PLATA | D35: PLATA | E35: ORO | G35: PLATA | O35: BRONCE
A36: C.Catán 4º | B36: PLATA | C36: ORO | E36: BRONCE
A37: Criquet | B37: PLATA | E37: BRONCE | F37: ORO | I37: BRONCE
A38: Dardos | B38: ORO
A39: Piscina | C39: ORO | D39: ORO | E39: PLATA | F39: ORO
A40: Piscina | C40: ORO | D40: ORO | E40: PLATA | F40: ORO
...

Sheet 2010
A1: 2010 | B1: David | C1: Carlos | D1: Laura | E1: Jorge | F1: Sergio | G1: Poli | H1: Nuria | I1: Sara | J1: Dario | K1: Pedro | L1: Inés | M1: Chema | N1: Maite | O1: Abuelos
A2: -1 | B2: PLATA | C2: ORO | D2: v | E2: v | F2: BRONCE | G2: x | H2: x | I2: x | J2: x | K2: x | L2: x | M2: x | N2: x | O2: x
A3: -1 | B3: PLATA | C3: BRONCE | D3: v | E3: ORO | F3: v | G3: v | H3: x | I3: x | J3: x | K3: x | L3: x | M3: x | N3: x | O3: x
A4: Fútbol | B4: ORO | C4: v | D4: ORO | E4: v | F4: ORO | G4: v | H4: x | I4: x | J4: x | K4: x | L4: x | M4: x | N4: x | O4: x
A5: Catán | B5: PLATA | C5: BRONCE | D5: ORO | E5: v | F5: PLATA | G5: ORO | H5: x | I5: x | J5: x | K5: x | L5: v | M5: v | N5: x | O5: x
A6: Catán | B6: v | C6: ORO | D6: v | E6: PLATA | F6: v | G6: v | H6: x | I6: x | J6: x | K6: x | L6: v | M6: PLATA | N6: x | O6: x
A7: Burro | B7: ORO | C7: PLATA | D7: v | E7: BRONCE | F7: v | G7: x | H7: x | I7: x | J7: x | K7: x | L7: x | M7: v | N7: x | O7: x
A8: Dardos | B8: ORO | C8: v | D8: v | E8: v | F8: PLATA | G8: x | H8: v | I8: ORO | J8: ORO | K8: x | L8: x | M8: BRONCE | N8: x | O8: x
A9: Mario Kart | B9: x | C9: PLATA | D9: v | E9: ORO | F9: BRONCE | G9: x | H9: x | I9: x | J9: x | K9: x | L9: x | M9: x | N9: x | O9: x
A10: Búsqueda de cosas | B10: x | C10: PLATA | D10: ORO | E10: PLATA | F10: BRONCE | G10: x | H10: x | I10: x | J10: x | K10: x | L10: x | M10: x | N10: x | O10: x
A11: Carrera | B11: x | C11: PLATA | D11: x | E11: ORO | F11: BRONCE | G11: x | H11: x | I11: x | J11: x | K11: x | L11: x | M11: x | N11: x | O11: x
A12: Sillas | B12: v | C12: v | D12: x | E12: ORO | F12: BRONCE | G12: PLATA | H12: v | I12: v | J12: x | K12: x | L12: x | M12: x | N12: x | O12: x
A13: Pañuelo | B13: v | C13: ORO | D13: v | E13: ORO | F13: v | G13: x | H13: v | I13: ORO | J13: x | K13: x | L13: x | M13: x | N13: x | O13: x
A14: Pañuelo | B14: v | C14: ORO | D14: x | E14: ORO | F14: v | G14: ORO | H14: v | I14: x | J14: x | K14: x | L14: x | M14: x | N14: x | O14: x
A15: Petanca | B15: PLATA | C15: PLATA | D15: ORO | E15: BRONCE | F15: BRONCE | G15: ORO | H15: PLATA | I15: x | J15: ORO | K15: x | L15: x | M15: x | N15: x | O15: x
... A74: Porra partido Holanda-España | B74: v | C74: v | D74: ORO | E74: ORO | F74: ORO | G74: v | H74: v | I74: v | J74: v | K74: x | L74: x | M74: x | N74: x | O74: v
A77: v | B77: {=SUM(IF(B2:B76="v",1))} -> 15 | C77: {=SUM(IF(C2:C76="v",1))} -> 27 | D77: {=SUM(IF(D2:D76="v",1))} -> 27 | E77: {=SUM(IF(E2:E76="v",1))} -> 25 | F77: {=SUM(IF(F2:F76="v",1))} -> 28 | G77: {=SUM(IF(G2:G76="v",1))} -> 12 | H77: {=SUM(IF(H2:H76="v",1))} -> 14 | I77: {=SUM(IF(I2:I76="v",1))} -> 16 | ... O77: {=SUM(IF(O2:O76="v",1))} -> 4
A78: x | B78: {=SUM(IF(B2:B76="x",1))} -> 24 | C78: {=SUM(IF(C2:C76="x",1))} -> 6 | D78: {=SUM(IF(D2:D76="x",1))} -> 16 | E78: {=SUM(IF(E2:E76="x",1))} -> 7 | F78: {=SUM(IF(F2:F76="x",1))} -> 8 | G78: {=SUM(IF(G2:G76="x",1))} -> 38 | H78: {=SUM(IF(H2:H76="x",1))} -> 47 | I78: {=SUM(IF(I2:I76="x",1))} -> 45 | ... O78: {=SUM(IF(O2:O76="x",1))} -> 67
A79: Participaciones | B79: =B77+B80+B81+B82 -> 49 | C79: =C77+C80+C81+C82 -> 67 | D79: =D77+D80+D81+D82 -> 57 | E79: =E77+E80+E81+E82 -> 66 | F79: =F77+F80+F81+F82 -> 65 | G79: =G77+G80+G81+G82 -> 35 | H79: =H77+H80+H81+H82 -> 26 | I79: =I77+I80+I81+I82 -> 28 | ... O79: =O77+O80+O81+O82 -> 6
A80: BRONCE | B80: {=SUM(IF(B$2:B$76=$A80,1))} -> 1 | C80: {=SUM(IF(C$2:C$76=$A80,1))} -> 9 | D80: {=SUM(IF(D$2:D$76=$A80,1))} -> 8 | E80: {=SUM(IF(E$2:E$76=$A80,1))} -> 15 | F80: {=SUM(IF(F$2:F$76=$A80,1))} -> 13 | G80: {=SUM(IF(G$2:G$76=$A80,1))} -> 7 | H80: {=SUM(IF(H$2:H$76=$A80,1))} -> 2 | I80: {=SUM(IF(I$2:I$76=$A80,1))} -> 3 | ... O80: {=SUM(IF(O$2:O$76=$A80,1))} -> 1
A81: PLATA | B81: {=SUM(IF(B$2:B$76=$A81,1))} -> 15 | C81: {=SUM(IF(C$2:C$76=$A81,1))} -> 16 | D81: {=SUM(IF(D$2:D$76=$A81,1))} -> 7 | E81: {=SUM(IF(E$2:E$76=$A81,1))} -> 9 | F81: {=SUM(IF(F$2:F$76=$A81,1))} -> 7 | G81: {=SUM(IF(G$2:G$76=$A81,1))} -> 4 | H81: {=SUM(IF(H$2:H$76=$A81,1))} -> 8 | I81: {=SUM(IF(I$2:I$76=$A81,1))} -> 3 | ... O81: {=SUM(IF(O$2:O$76=$A81,1))} -> 0
A82: ORO | B82: {=SUM(IF(B$2:B$76=$A82,1))} -> 18 | C82: {=SUM(IF(C$2:C$76=$A82,1))} -> 15 | D82: {=SUM(IF(D$2:D$76=$A82,1))} -> 15 | E82: {=SUM(IF(E$2:E$76=$A82,1))} -> 17 | F82: {=SUM(IF(F$2:F$76=$A82,1))} -> 17 | G82: {=SUM(IF(G$2:G$76=$A82,1))} -> 12 | H82: {=SUM(IF(H$2:H$76=$A82,1))} -> 2 | I82: {=SUM(IF(I$2:I$76=$A82,1))} -> 6 | ... O82: {=SUM(IF(O$2:O$76=$A82,1))} -> 1
A83: Puntos | B83: =B80+B81*2+B82*3 -> 85 | C83: =C80+C81*2+C82*3 -> 86 | D83: =D80+D81*2+D82*3 -> 67 | E83: =E80+E81*2+E82*3 -> 84 | F83: =F80+F81*2+F82*3 -> 78 | G83: =G80+G81*2+G82*3 -> 51 | H83: =H80+H81*2+H82*3 -> 24 | I83: =I80+I81*2+I82*3 -> 27 | ... O83: =O80+O81*2+O82*3 -> 4
A84: Promedio | B84: =IF(B77+B80+B81+B82<>0,B83/(B77+B80+B81+B82),0) -> 1.7346939 | C84: =IF(C77+C80+C81+C82<>0,C83/(C77+C80+C81+C82),0) -> 1.2835821 | D84: =IF(D77+D80+D81+D82<>0,D83/(D77+D80+D81+D82),0) -> 1.1754386 | E84: =IF(E77+E80+E81+E82<>0,E83/(E77+E80+E81+E82),0) -> 1.2727273 | F84: =IF(F77+F80+F81+F82<>0,F83/(F77+F80+F81+F82),0) -> 1.2 | G84: =IF(G77+G80+G81+G82<>0,G83/(G77+G80+G81+G82),0) -> 1.4571429 | H84: =IF(H77+H80+H81+H82<>0,H83/(H77+H80+H81+H82),0) -> 0.92307692 | I84: =IF(I77+I80+I81+I82<>0,I83/(I77+I80+I81+I82),0) -> 0.96428571 | ... O84: =IF(O77+O80+O81+O82<>0,O83/(O77+O80+O81+O82),0) -> 0.66666667
A85: Check | B85: =B79+B78 -> 73 | C85: =C79+C78 -> 73 | D85: =D79+D78 -> 73 | E85: =E79+E78 -> 73 | F85: =F79+F78 -> 73 | G85: =G79+G78 -> 73 | H85: =H79+H78 -> 73 | I85: =I79+I78 -> 73 | ... O85: =O79+O78 -> 73
A87: Daypo | B87: =B83+G83+H83+I83 -> 187 | D87: Daypo adultos | E87: =B83+G83 -> 136 | G87: Daypo jóvenes | H87: participaciones | I87: =B79+G79+H79+I79 -> 138 | K87: =B87/I87 -> 1.3550725 | L87: =I83+J83 -> 51 | O87: promedio
A88: Castrillo | B88: =C83+E83+L83+M83 -> 173 | D88: Castrillo adulto | E88: =L83+M83 -> 3 | G88: Castrillo jóvenes | H88: participaciones | I88: =C79+E79+L79+H79 -> 161 | K88: =B88/I88 -> 1.0745342 | L88: =C83+E83+H83 -> 194 | O88: promedio
A89: Arroni Del Riego | B89: =D83+F83+O83+K83 -> 188 | D89: Del Riego adulto | E89: =K83+N83 -> 48 | G89: Del Riego jóvenes | H89: participaciones | I89: =D79+F79+K79+N79 -> 154 | K89: =B89/I89 -> 1.2207792 | L89: =D83+F83 -> 145 | O89: promedio
A91: Jóvenes | B91: =C83+D83+E83+F83+M83+H83+B92 -> 545
A92: Adultos | B92: =B83+G83+L83+J83+O83+K83 -> 203
A94: Campeón | B94: Carlos
A96: Victorias totales | B96: 1 | C96: 1 | D96: 0 | E96: 0 | F96: 0 | G96: 0 | H96: 0 | I96: 0 | J96: 0 | K96: 0 | L96: 0 | M96: 0 | N96: 0 | O96: 0
B101: ORO=3
B102: PLATA=2
B103: BRONCE=1

Sheet 2011
A1: 2011 | B1: David | C1: Carlos | D1: Laura | E1: Jorge | F1: Sergio | G1: Poli | H1: Nuria | I1: Sara | J1: Dario | K1: Pedro | L1: Inés | M1: Chema | N1: Maite | O1: Anuncia | P1: Roberto
A2: Baloncesto | B2: ORO | C2: x | D2: PLATA | E2: x | F2: PLATA | G2: PLATA | H2: x | I2: x | J2: x | K2: x | L2: x | M2: x | N2: x | O2: x | P2: x
A3: Salto | B3: ORO | C3: x | D3: v | E3: x | F3: BRONCE | G3: PLATA | H3: x | I3: PLATA | J3: BRONCE | K3: x | L3: x | M3: x | N3: x | O3: x | P3: x
A4: Cocodrilo | B4: x | C4: x | D4: x | E4: x | F4: ORO | G4: x | H4: x | I4: x | J4: x | K4: x | L4: x | M4: x | N4: x | O4: x | P4: x
A5: Cocodrilo | B5: x | C5: x | D5: x | E5: x | F5: PLATA | G5: x | H5: x | I5: x | J5: x | K5: x | L5: x | M5: x | N5: x | O5: x | P5: x
A6: Catán | B6: ORO | C6: x | D6: PLATA | E6: x | F6: BRONCE | G6: v | H6: x | I6: x | J6: x | K6: x | L6: x | M6: x | N6: x | O6: BRONCE | P6: x
A7: Petanca | B7: ORO | C7: x | D7: v | E7: x | F7: ORO | G7: BRONCE | H7: x | I7: v | J7: BRONCE | K7: x | L7: x | M7: x | N7: x | O7: PLATA | P7: x
A8: Fútbol | B8: v | C8: ORO | D8: v | E8: v | F8: ORO | G8: ORO | H8: x | I8: x | J8: ORO | K8: x | L8: x | M8: x | N8: x | O8: x | P8: x
A9: -1 | B9: ORO | C9: PLATA | D9: v | E9: BRONCE | F9: v | G9: x | H9: x | I9: x | J9: x | K9: x | L9: v | M9: x | N9: x | O9: x | P9: x
A10: Catán | B10: BRONCE | C10: BRONCE | D10: v | E10: BRONCE | F10: PLATA | G10: ORO | H10: x | I10: x | J10: x | K10: x | L10: x | M10: x | N10: x | O10: x | P10: x
A11: Tirar bici | B11: x | C11: ORO | D11: x | E11: BRONCE | F11: PLATA | G11: v | H11: x | I11: x | J11: x | K11: x | L11: x | M11: x | N11: x | O11: x | P11: x
A12: Frontón | B12: ORO | C12: BRONCE | D12: PLATA | E12: ORO | F12: BRONCE | G12: PLATA | H12: x | I12: x | J12: x | K12: x | L12: x | M12: x | N12: x | O12: x | P12: x
A13: Carrera bici infantil | B13: x | C13: x | D13: x | E13: x | F13: x | G13: x | H13: x | I13: ORO | J13: PLATA | K13: x | L13: x | M13: x | N13: x | O13: x | P13: x
A14: Carrera bici adulto | B14: ORO | C14: PLATA | D14: v | E14: v | F14: v | G14: BRONCE | H14: x | I14: x | J14: x | K14: x | L14: x | M14: x | N14: x | O14: x | P14: x
A15: Tirar bici | B15: ORO | C15: PLATA | D15: x | E15: v | F15: BRONCE | G15: x | H15: x | I15: x | J15: x | K15: x | L15: x | M15: x | N15: x | O15: x | P15: x
A16: Apuesta | B16: x | C16: BRONCE | D16: x | E16: x | F16: x | G16: x | H16: x | I16: x | J16: x | K16: x | L16: x | M16: x | N16: x | O16: x | P16: x
A17: Carrera bici | B17: x | C17: v | D17: ORO | E17: BRONCE | F17: PLATA | G17: x | H17: x | I17: x | J17: x | K17: x | L17: x | M17: x | N17: x | O17: x | P17: x
A18: Petanca | B18: PLATA | C18: v | D18: PLATA | E18: v | F18: PLATA | G18: ORO | H18: v | I18: v | J18: PLATA | K18: x | L18: x | M18: x | N18: x | O18: ORO | P18: x
A19: Catán | B19: v | C19: ORO | D19: v | E19: v | F19: BRONCE | G19: PLATA | H19: x | I19: x | J19: x | K19: x | L19: x | M19: x | N19: x | O19: x | P19: x
A20: Gimcana infantil | B20: x | C20: x | D20: x | E20: x | F20: x | G20: x | H20: ORO | I20: PLATA | J20: BRONCE | K20: x | L20: x | M20: x | N20: x | O20: x | P20: x
A21: Gimcana adulto | B21: ORO | C21: v | D21: v | E21: v | F21: PLATA | G21: BRONCE | H21: x | I21: x | J21: x | K21: x | L21: x | M21: x | N21: x | O21: x | P21: x
... A82: Tirar papel higiénico | B82: x | C82: v | D82: v | E82: v | F82: v | G82: x | H82: x | I82: x | J82: x | K82: ORO | L82: x | M82: x | N82: x | O82: x | P82: x
A100: v | B100: {=SUM(IF(B2:B99="v",1))} -> 8 | C100: {=SUM(IF(C2:C99="v",1))} -> 22 | D100: {=SUM(IF(D2:D99="v",1))} -> 25 | E100: {=SUM(IF(E2:E99="v",1))} -> 19 | F100: {=SUM(IF(F2:F99="v",1))} -> 24 | G100: {=SUM(IF(G2:G99="v",1))} -> 7 | H100: {=SUM(IF(H2:H99="v",1))} -> 7 | I100: {=SUM(IF(I2:I99="v",1))} -> 10 | ... P100: {=SUM(IF(P2:P99="v",1))} -> 1
A101: x | B101: {=SUM(IF(B2:B99="x",1))} -> 41 | C101: {=SUM(IF(C2:C99="x",1))} -> 16 | D101: {=SUM(IF(D2:D99="x",1))} -> 20 | E101: {=SUM(IF(E2:E99="x",1))} -> 19 | F101: {=SUM(IF(F2:F99="x",1))} -> 11 | G101: {=SUM(IF(G2:G99="x",1))} -> 53 | H101: {=SUM(IF(H2:H99="x",1))} -> 61 | I101: {=SUM(IF(I2:I99="x",1))} -> 54 | ... P101: {=SUM(IF(P2:P99="x",1))} -> 79
A102: Participaciones | B102: =B100+B103+B104+B105 -> 40 | C102: =C100+C103+C104+C105 -> 65 | D102: =D100+D103+D104+D105 -> 61 | E102: =E100+E103+E104+E105 -> 62 | F102: =F100+F103+F104+F105 -> 70 | G102: =G100+G103+G104+G105 -> 28 | H102: =H100+H103+H104+H105 -> 20 | I102: =I100+I103+I104+I105 -> 27 | ... P102: =P100+P103+P104+P105 -> 2
A103: BRONCE | B103: {=SUM(IF(B$2:B$99=$A103,1))} -> 4 | C103: {=SUM(IF(C$2:C$99=$A103,1))} -> 12 | D103: {=SUM(IF(D$2:D$99=$A103,1))} -> 7 | E103: {=SUM(IF(E$2:E$99=$A103,1))} -> 15 | F103: {=SUM(IF(F$2:F$99=$A103,1))} -> 16 | G103: {=SUM(IF(G$2:G$99=$A103,1))} -> 6 | H103: {=SUM(IF(H$2:H$99=$A103,1))} -> 1 | I103: {=SUM(IF(I$2:I$99=$A103,1))} -> 4 | ... P103: {=SUM(IF(P$2:P$99=$A103,1))} -> 1
A104: PLATA | B104: {=SUM(IF(B$2:B$99=$A104,1))} -> 9 | C104: {=SUM(IF(C$2:C$99=$A104,1))} -> 16 | D104: {=SUM(IF(D$2:D$99=$A104,1))} -> 14 | E104: {=SUM(IF(E$2:E$99=$A104,1))} -> 10 | F104: {=SUM(IF(F$2:F$99=$A104,1))} -> 18 | G104: {=SUM(IF(G$2:G$99=$A104,1))} -> 7 | H104: {=SUM(IF(H$2:H$99=$A104,1))} -> 5 | I104: {=SUM(IF(I$2:I$99=$A104,1))} -> 6 | ... P104: {=SUM(IF(P$2:P$99=$A104,1))} -> 0
A105: ORO | B105: {=SUM(IF(B$2:B$99=$A105,1))} -> 19 | C105: {=SUM(IF(C$2:C$99=$A105,1))} -> 15 | D105: {=SUM(IF(D$2:D$99=$A105,1))} -> 15 | E105: {=SUM(IF(E$2:E$99=$A105,1))} -> 18 | F105: {=SUM(IF(F$2:F$99=$A105,1))} -> 12 | G105: {=SUM(IF(G$2:G$99=$A105,1))} -> 8 | H105: {=SUM(IF(H$2:H$99=$A105,1))} -> 7 | I105: {=SUM(IF(I$2:I$99=$A105,1))} -> 7 | ... P105: {=SUM(IF(P$2:P$99=$A105,1))} -> 0
A106: Puntos | B106: =B103+B104*2+B105*3 -> 79 | C106: =C103+C104*2+C105*3 -> 89 | D106: =D103+D104*2+D105*3 -> 80 | E106: =E103+E104*2+E105*3 -> 89 | F106: =F103+F104*2+F105*3 -> 88 | G106: =G103+G104*2+G105*3 -> 44 | H106: =H103+H104*2+H105*3 -> 32 | I106: =I103+I104*2+I105*3 -> 37 | ... P106: =P103+P104*2+P105*3 -> 1
A107: Promedio | B107: =IF(B100+B103+B104+B105<>0,B106/(B100+B103+B104+B105),0) -> 1.975 | C107: =IF(C100+C103+C104+C105<>0,C106/(C100+C103+C104+C105),0) -> 1.3692308 | D107: =IF(D100+D103+D104+D105<>0,D106/(D100+D103+D104+D105),0) -> 1.3114754 | E107: =IF(E100+E103+E104+E105<>0,E106/(E100+E103+E104+E105),0) -> 1.4354839 | F107: =IF(F100+F103+F104+F105<>0,F106/(F100+F103+F104+F105),0) -> 1.2571429 | G107: =IF(G100+G103+G104+G105<>0,G106/(G100+G103+G104+G105),0) -> 1.5714286 | H107: =IF(H100+H103+H104+H105<>0,H106/(H100+H103+H104+H105),0) -> 1.6 | I107: =IF(I100+I103+I104+I105<>0,I106/(I100+I103+I104+I105),0) -> 1.3703704 | ... P107: =IF(P100+P103+P104+P105<>0,P106/(P100+P103+P104+P105),0) -> 0.5
A108: Check | B108: =B102+B101 -> 81 | C108: =C102+C101 -> 81 | D108: =D102+D101 -> 81 | E108: =E102+E101 -> 81 | F108: =F102+F101 -> 81 | G108: =G102+G101 -> 81 | H108: =H102+H101 -> 81 | I108: =I102+I101 -> 81 | ... P108: =P102+P101 -> 81
A110: Daypo | B110: =B106+G106+I106+J106 -> 189 | D110: Daypo adultos | E110: =B106+G106 -> 123 | G110: Daypo jóvenes | I110: participaciones | J110: =B102+G102+I102+J102 -> 113 | K110: promedio | L110: =I106+J106 -> 66 | N110: =B110/J110 -> 1.6725664
A111: Castrillo | B111: =C106+E106+L106+H106 -> 210 | D111: Castrillo adulto | E111: =L106 -> 0 | G111: Castrillo jóvenes | I111: participaciones | J111: =C102+E102+L102+H102 -> 149 | K111: promedio | L111: =C106+E106+H106 -> 210 | N111: =B111/J111 -> 1.409396
A112: Arroni Del Riego | B112: =D106+F106+K106+N106 -> 192 | D112: Del Riego adulto | E112: =K106+N106 -> 24 | G112: Del Riego jóvenes | I112: participaciones | J112: =D102+F102+K102+N102 -> 149 | K112: promedio | L112: =D106+F106 -> 168 | N112: =B112/J112 -> 1.2885906
A114: Jóvenes | B114: =C106+D106+E106+F106+H106+I106+B115 -> 572
A115: Adultos | B115: =B106+G106+L106+O106+K106+N106+P106 -> 157
A117: Campeón | B117: Carlos y Jorge
A119: Victorias totales | B119: 1 | C119: 2 | D119: 0 | E119: 1 | F119: 0 | G119: 0 | H119: 0 | I119: 0 | J119: 0 | K119: 0 | L119: 0 | N119: 0 | O119: 0 | P119: 0

Sheet 2012
A1: 2012 | B1: David | C1: Carlos | D1: Laura | E1: Jorge | F1: Sergio | G1: Poli | H1: Nuria | I1: Sara | J1: Dario | K1: Pedro | L1: Inés | M1: Chema | N1: Maite | O1: Anuncia | P1: Roberto
A2: Cartas | B2: PLATA | C2: x | D2: x | E2: x | F2: PLATA | G2: ORO | H2: x | I2: v | J2: v | K2: x | L2: x | M2: x | N2: x | O2: v | P2: x
A3: Badminton | B3: PLATA | C3: x | D3: ORO | E3: x | F3: PLATA | G3: ORO | H3: x | I3: x | J3: x | K3: x | L3: x | M3: x | N3: x | O3: x | P3: x
A4: Volley | B4: ORO | C4: x | D4: PLATA | E4: x | F4: ORO | G4: PLATA | H4: x | I4: x | J4: x | K4: x | L4: x | M4: x | N4: x | O4: x | P4: x
A5: Lanzamiento pelota en distancia Jr. | B5: x | C5: x | D5: x | E5: x | F5: x | G5: x | H5: BRONCE | I5: ORO | J5: PLATA | K5: x | L5: x | M5: x | N5: x | O5: x | P5: x
A6: Lanzamiento pelota en distancia Sr. | B6: ORO | C6: v | D6: BRONCE | E6: PLATA | F6: v | G6: x | H6: x | I6: x | J6: x | K6: x | L6: x | M6: x | N6: x | O6: x | P6: x
A7: Canasta en piscina | B7: v | C7: v | D7: v | E7: v | F7: ORO | G7: x | H7: v | I7: PLATA | J7: x | K7: x | L7: x | M7: x | N7: x | O7: x | P7: x
A8: Petanca con pelota de tenis desde balcón | B8: BRONCE | C8: PLATA | D8: v | E8: v | F8: v | G8: x | H8: ORO | I8: v | J8: x | K8: x | L8: x | M8: x | N8: x | O8: x | P8: x
A9: Lanzamiento badminton desde balcón | B9: v | C9: PLATA | D9: BRONCE | E9: ORO | F9: v | G9: x | H9: x | I9: x | J9: x | K9: x | L9: x | M9: x | N9: x | O9: x | P9: x
A10: Mario Kart | B10: x | C10: PLATA | D10: PLATA | E10: ORO | F10: BRONCE | G10: x | H10: x | I10: x | J10: v | K10: x | L10: x | M10: x | N10: x | O10: x | P10: x
A11: Petanca con peloTa de badminton desde balcón | B11: PLATA | C11: BRONCE | D11: v | E11: ORO | F11: v | G11: x | H11: x | I11: x | J11: x | K11: x | L11: x | M11: x | N11: x | O11: x | P11: x
A12: Call of Duty | B12: x | C12: x | D12: PLATA | E12: ORO | F12: BRONCE | G12: x | H12: x | I12: x | J12: x | K12: x | L12: x | M12: x | N12: x | O12: x | P12: x
A13: Resistencia en agua Jr. | B13: x | C13: x | D13: x | E13: x | F13: x | G13: x | H13: ORO | I13: BRONCE | J13: PLATA | K13: x | L13: x | M13: x | N13: x | O13: x | P13: x
... A16: Fútbol | B16: ORO | C16: v | D16: x | E16: ORO | F16: v | G16: v | H16: x | I16: x | J16: x | K16: x | L16: ORO | M16: x | N16: x | O16: x | P16: x
A17: -1 | B17: PLATA | C17: v | D17: x | E17: x | F17: BRONCE | G17: ORO | H17: x | I17: x | J17: x | K17: x | L17: x | M17: x | N17: x | O17: x | P17: x
A18: Carrera en bici | B18: x | C18: PLATA | D18: x | E18: BRONCE | F18: ORO | G18: x | H18: x | I18: x | J18: x | K18: x | L18: x | M18: x | N18: x | O18: x | P18: x
A19: Catán | B19: ORO | C19: PLATA | D19: BRONCE | E19: BRONCE | F19: v | G19: v | H19: x | I19: x | J19: x | K19: x | L19: v | M19: x | N19: x | O19: x | P19: x
A20: Escondite en bici | B20: v | C20: ORO | D20: x | E20: ORO | F20: v | G20: v | H20: x | I20: v | J20: v | K20: x | L20: x | M20: x | N20: x | O20: x | P20: x
A21: Aceleración en bici | B21: PLATA | C21: ORO | D21: x | E21: v | F21: v | G21: x | H21: x | I21: x | J21: BRONCE | K21: x | L21: x | M21: x | N21: x | O21: x | P21: x
A22: English | B22: x | C22: PLATA | D22: v | E22: ORO | F22: BRONCE | G22: x | H22: x | I22: x | J22: x | K22: x | L22: x | M22: x | N22: x | O22: x | P22: x
A23: Baloncesto | B23: ORO | C23: v | D23: x | E23: v | F23: ORO | G23: x | H23: x | I23: x | J23: x | K23: x | L23: x | M23: x | N23: x | O23: x | P23: x
A24: Futbolin | B24: ORO | C24: BRONCE | D24: PLATA | E24: v | F24: v | G24: x | H24: x | I24: x | J24: x | K24: x | L24: x | M24: x | N24: x | O24: x | P24: x
A25: Dardos | B25: ORO | C25: PLATA | D25: x | E25: v | F25: v | G25: BRONCE | H25: x | I25: x | J25: x | K25: x | L25: v | M25: x | N25: x | O25: v | P25: x
A26: Carrera lenta en bici | B26: PLATA | C26: ORO | D26: x | E26: v | F26: v | G26: x | H26: x | I26: x | J26: x | K26: x | L26: x | M26: x | N26: x | O26: x | P26: x
A27: Cartas: El pueblo | B27: ORO | C27: v | D27: v | E27: v | F27: PLATA | G27: PLATA | H27: x | I27: x | J27: x | K27: x | L27: v | M27: x | N27: x | O27: PLATA | P27: x
A28: La Rana | B28: x | C28: v | D28: v | E28: v | F28: ORO | G28: x | H28: v | I28: v | J28: ORO | K28: x | L28: x | M28: x | N28: x | O28: x | P28: x
A29: Buscar bajo agua Jr. Animales | B29: x | C29: x | D29: x | E29: x | F29: x | G29: x | H29: ORO | I29: PLATA | J29: BRONCE | K29: x | L29: x | M29: x | N29: x | O29: x | P29: x
... A77: Volley | B77: ORO | C77: v | D77: v | E77: ORO | F77: v | G77: ORO | H77: x | I77: x | J77: x | K77: v | L77: x | M77: x | N77: ORO | O77: x | P77: x
A100: v | B100: {=SUM(IF(B2:B99="v",1))} -> 6 | C100: {=SUM(IF(C2:C99="v",1))} -> 18 | D100: {=SUM(IF(D2:D99="v",1))} -> 12 | E100: {=SUM(IF(E2:E99="v",1))} -> 22 | F100: {=SUM(IF(F2:F99="v",1))} -> 26 | G100: {=SUM(IF(G2:G99="v",1))} -> 4 | H100: {=SUM(IF(H2:H99="v",1))} -> 3 | I100: {=SUM(IF(I2:I99="v",1))} -> 6 | ... P100: {=SUM(IF(P2:P99="v",1))} -> 0
A101: x | B101: {=SUM(IF(B2:B99="x",1))} -> 36 | C101: {=SUM(IF(C2:C99="x",1))} -> 20 | D101: {=SUM(IF(D2:D99="x",1))} -> 41 | E101: {=SUM(IF(E2:E99="x",1))} -> 19 | F101: {=SUM(IF(F2:F99="x",1))} -> 15 | G101: {=SUM(IF(G2:G99="x",1))} -> 56 | H101: {=SUM(IF(H2:H99="x",1))} -> 56 | I101: {=SUM(IF(I2:I99="x",1))} -> 52 | ... P101: {=SUM(IF(P2:P99="x",1))} -> 76
A102: Participaciones | B102: =B100+B103+B104+B105 -> 40 | C102: =C100+C103+C104+C105 -> 56 | D102: =D100+D103+D104+D105 -> 35 | E102: =E100+E103+E104+E105 -> 57 | F102: =F100+F103+F104+F105 -> 61 | G102: =G100+G103+G104+G105 -> 20 | H102: =H100+H103+H104+H105 -> 20 | I102: =I100+I103+I104+I105 -> 24 | ... P102: =P100+P103+P104+P105 -> 0
A103: BRONCE | B103: {=SUM(IF(B$2:B$99=$A103,1))} -> 2 | C103: {=SUM(IF(C$2:C$99=$A103,1))} -> 8 | D103: {=SUM(IF(D$2:D$99=$A103,1))} -> 7 | E103: {=SUM(IF(E$2:E$99=$A103,1))} -> 12 | F103: {=SUM(IF(F$2:F$99=$A103,1))} -> 12 | G103: {=SUM(IF(G$2:G$99=$A103,1))} -> 5 | H103: {=SUM(IF(H$2:H$99=$A103,1))} -> 6 | I103: {=SUM(IF(I$2:I$99=$A103,1))} -> 2 | ... P103: {=SUM(IF(P$2:P$99=$A103,1))} -> 0
A104: PLATA | B104: {=SUM(IF(B$2:B$99=$A104,1))} -> 12 | C104: {=SUM(IF(C$2:C$99=$A104,1))} -> 18 | D104: {=SUM(IF(D$2:D$99=$A104,1))} -> 10 | E104: {=SUM(IF(E$2:E$99=$A104,1))} -> 8 | F104: {=SUM(IF(F$2:F$99=$A104,1))} -> 8 | G104: {=SUM(IF(G$2:G$99=$A104,1))} -> 4 | H104: {=SUM(IF(H$2:H$99=$A104,1))} -> 5 | I104: {=SUM(IF(I$2:I$99=$A104,1))} -> 9 | ... P104: {=SUM(IF(P$2:P$99=$A104,1))} -> 0
A105: ORO | B105: {=SUM(IF(B$2:B$99=$A105,1))} -> 20 | C105: {=SUM(IF(C$2:C$99=$A105,1))} -> 12 | D105: {=SUM(IF(D$2:D$99=$A105,1))} -> 6 | E105: {=SUM(IF(E$2:E$99=$A105,1))} -> 15 | F105: {=SUM(IF(F$2:F$99=$A105,1))} -> 15 | G105: {=SUM(IF(G$2:G$99=$A105,1))} -> 7 | H105: {=SUM(IF(H$2:H$99=$A105,1))} -> 6 | I105: {=SUM(IF(I$2:I$99=$A105,1))} -> 7 | ... P105: {=SUM(IF(P$2:P$99=$A105,1))} -> 0
A106: Puntos | B106: =B103+B104*2+B105*3 -> 86 | C106: =C103+C104*2+C105*3 -> 80 | D106: =D103+D104*2+D105*3 -> 45 | E106: =E103+E104*2+E105*3 -> 73 | F106: =F103+F104*2+F105*3 -> 73 | G106: =G103+G104*2+G105*3 -> 34 | H106: =H103+H104*2+H105*3 -> 34 | I106: =I103+I104*2+I105*3 -> 41 | ... P106: =P103+P104*2+P105*3 -> 0
A107: Promedio | B107: =IF(B100+B103+B104+B105<>0,B106/(B100+B103+B104+B105),0) -> 2.15 | C107: =IF(C100+C103+C104+C105<>0,C106/(C100+C103+C104+C105),0) -> 1.4285714 | D107: =IF(D100+D103+D104+D105<>0,D106/(D100+D103+D104+D105),0) -> 1.2857143 | E107: =IF(E100+E103+E104+E105<>0,E106/(E100+E103+E104+E105),0) -> 1.2807018 | F107: =IF(F100+F103+F104+F105<>0,F106/(F100+F103+F104+F105),0) -> 1.1967213 | G107: =IF(G100+G103+G104+G105<>0,G106/(G100+G103+G104+G105),0) -> 1.7 | H107: =IF(H100+H103+H104+H105<>0,H106/(H100+H103+H104+H105),0) -> 1.7 | I107: =IF(I100+I103+I104+I105<>0,I106/(I100+I103+I104+I105),0) -> 1.7083333 | ... P107: =IF(P100+P103+P104+P105<>0,P106/(P100+P103+P104+P105),0) -> 0
A108: Check | B108: =B102+B101 -> 76 | C108: =C102+C101 -> 76 | D108: =D102+D101 -> 76 | E108: =E102+E101 -> 76 | F108: =F102+F101 -> 76 | G108: =G102+G101 -> 76 | H108: =H102+H101 -> 76 | I108: =I102+I101 -> 76 | ... P108: =P102+P101 -> 76
A110: Daypo | B110: =B106+G106+I106+J106 -> 188 | D110: Daypo adultos | E110: =B106+G106 -> 120 | G110: Daypo jóvenes | I110: participaciones | J110: =B102+G102+I102+J102 -> 106 | K110: promedio | L110: =I106+J106 -> 68 | N110: =B110/J110 -> 1.7735849
A111: Castrillo | B111: =C106+E106+L106+H106 -> 190 | D111: Castrillo adulto | E111: =L106 -> 3 | G111: Castrillo jóvenes | I111: participaciones | J111: =C102+E102+L102+H102 -> 137 | K111: promedio | L111: =C106+E106+H106 -> 187 | N111: =B111/J111 -> 1.3868613
A112: Arroni Del Riego | B112: =D106+F106+K106+N106 -> 129 | D112: Del Riego adulto | E112: =K106+N106 -> 11 | G112: Del Riego jóvenes | I112: participaciones | J112: =D102+F102+K102+N102 -> 106 | K112: promedio | L112: =D106+F106 -> 118 | N112: =B112/J112 -> 1.2169811
...

Sheet 2013
A1: 2013 | B1: David | C1: Carlos | D1: Laura | E1: Jorge | F1: Sergio | G1: Poli | H1: Nuria | I1: Sara | J1: Dario | K1: Pedro | L1: Inés | M1: Chema | N1: Maite | O1: Anuncia | P1: Roberto
A2: Fútbol | B2: ORO | C2: v | D2: x | E2: v | F2: v | G2: v | H2: x | I2: x | J2: x | K2: ORO | L2: x | M2: ORO | N2: x | O2: x | P2: x
A3: Fútbol | B3: ORO | C3: v | D3: x | E3: v | F3: ORO | G3: v | H3: x | I3: x | J3: x | K3: v | L3: x | M3: ORO | N3: x | O3: x | P3: x
A4: Call of Duty | B4: x | C4: v | D4: x | E4: ORO | F4: ORO | G4: x | H4: x | I4: x | J4: x | K4: v | L4: x | M4: x | N4: x | O4: x | P4: x
A5: Futbolín | B5: v | C5: v | D5: x | E5: v | F5: ORO | G5: x | H5: x | I5: x | J5: ORO | K5: ORO | L5: x | M5: x | N5: x | O5: x | P5: x
A6: Frontón | B6: PLATA | C6: PLATA | D6: x | E6: BRONCE | F6: ORO | G6: BRONCE | H6: x | I6: x | J6: x | K6: ORO | L6: x | M6: x | N6: x | O6: x | P6: x
A7: Ajedrez | B7: v | C7: BRONCE | D7: x | E7: v | F7: ORO | G7: x | H7: x | I7: x | J7: v | K7: ORO | L7: x | M7: x | N7: x | O7: x | P7: x
A8: Minecraft | B8: x | C8: PLATA | D8: x | E8: ORO | F8: PLATA | G8: x | H8: x | I8: x | J8: v | K8: ORO | L8: x | M8: x | N8: x | O8: x | P8: x
A9: -1 | B9: x | C9: x | D9: x | E9: x | F9: x | G9: x | H9: x | I9: x | J9: x | K9: PLATA | L9: ORO | M9: x | N9: x | O9: x | P9: x
A10: -1 | B10: x | C10: x | D10: x | E10: x | F10: ORO | G10: x | H10: x | I10: x | J10: x | K10: PLATA | L10: BRONCE | M10: x | N10: x | O10: x | P10: x
A11: Catán | B11: v | C11: PLATA | D11: x | E11: v | F11: ORO | G11: v | H11: v | I11: x | J11: v | K11: PLATA | L11: x | M11: v | N11: x | O11: x | P11: x
A12: Mario Kart | B12: x | C12: PLATA | D12: x | E12: ORO | F12: ORO | G12: x | H12: x | I12: x | J12: PLATA | K12: x | L12: x | M12: x | N12: x | O12: x | P12: x
A13: Aguantar bajo el agua Jr. | B13: x | C13: x | D13: x | E13: x | F13: x | G13: x | H13: PLATA | I13: BRONCE | J13: ORO | K13: x | L13: x | M13: x | N13: x | O13: x | P13: x
A14: Dardos | B14: PLATA | C14: v | D14: x | E14: v | F14: v | G14: x | H14: v | I14: BRONCE | J14: x | K14: ORO | L14: v | M14: x | N14: x | O14: x | P14: x
A15: Petanca | B15: v | C15: ORO | D15: x | E15: PLATA | F15: PLATA | G15: x | H15: v | I15: v | J15: v | K15: x | L15: x | M15: x | N15: x | O15: x | P15: x
A16: Petanca | B16: x | C16: BRONCE | D16: x | E16: BRONCE | F16: BRONCE | G16: x | H16: x | I16: x | J16: x | K16: x | L16: v | M16: PLATA | N16: x | O16: ORO | P16: x
A17: PS2 Formula 1 con volante | B17: BRONCE | C17: ORO | D17: x | E17: PLATA | F17: v | G17: x | H17: x | I17: x | J17: x | K17: x | L17: x | M17: x | N17: x | O17: x | P17: x
A18: Call of Duty | B18: PLATA | C18: BRONCE | D18: x | E18: PLATA | F18: ORO | G18: x | H18: x | I18: x | J18: x | K18: x | L18: x | M18: x | N18: x | O18: x | P18: x
A19: -1 | B19: PLATA | C19: BRONCE | D19: x | E19: ORO | F19: BRONCE | G19: v | H19: x | I19: x | J19: x | K19: x | L19: x | M19: x | N19: x | O19: x | P19: x
A20: Baloncesto | B20: ORO | C20: v | D20: x | E20: v | F20: ORO | G20: v | H20: x | I20: x | J20: x | K20: x | L20: x | M20: x | N20: x | O20: x | P20: x
A21: Lanzamiento avión de papel | B21: BRONCE | C21: v | D21: x | E21: PLATA | F21: ORO | G21: x | H21: x | I21: x | J21: BRONCE | K21: x | L21: x | M21: x | N21: x | O21: v | P21: x
A22: Lanzamiento de pelota a piscina | B22: ORO | C22: v | D22: x | E22: v | F22: v | G22: x | H22: x | I22: x | J22: v | K22: x | L22: x | M22: x | N22: x | O22: v | P22: x
A23: Lanzamiento de pelota en distancia | B23: ORO | C23: v | D23: x | E23: BRONCE | F23: PLATA | G23: x | H23: x | I23: x | J23: v | K23: x | L23: x | M23: x | N23: x | O23: v | P23: x
A24: Proximidad bádminton | B24: PLATA | C24: PLATA | D24: x | E24: v | F24: ORO | G24: x | H24: x | I24: v | J24: v | K24: x | L24: x | M24: x | N24: x | O24: x | P24: x
A25: Lanzamiento de bádminton | B25: ORO | C25: PLATA | D25: x | E25: BRONCE | F25: v | G25: x | H25: x | I25: v | J25: v | K25: x | L25: x | M25: x | N25: x | O25: x | P25: x
A26: Toques bádminton | B26: v | C26: PLATA | D26: x | E26: v | F26: BRONCE | G26: ORO | H26: v | I26: x | J26: x | K26: x | L26: x | M26: x | N26: x | O26: x | P26: x
A27: Catán | B27: BRONCE | C27: v | D27: x | E27: v | F27: PLATA | G27: x | H27: v | I27: v | J27: x | K27: x | L27: x | M27: ORO | N27: x | O27: x | P27: x
A28: BICI El que más lejos llegue | B28: ORO | C28: PLATA | D28: x | E28: PLATA | F28: BRONCE | G28: x | H28: x | I28: PLATA | J28: v | K28: x | L28: x | M28: x | N28: x | O28: x | P28: x
A29: BICI Aceleración | B29: PLATA | C29: ORO | D29: x | E29: BRONCE | F29: v | G29: x | H29: x | I29: v | J29: v | K29: x | L29: x | M29: x | N29: x | O29: x | P29: x
A30: BICI Escondite | B30: BRONCE | C30: ORO | D30: x | E30: PLATA | F30: PLATA | G30: x | H30: BRONCE | I30: ORO | J30: BRONCE | K30: x | L30: x | M30: x | N30: x | O30: x | P30: x
A31: Criquet | B31: ORO | C31: PLATA | D31: x | E31: BRONCE | F31: v | G31: x | H31: v | I31: x | J31: v | K31: x | L31: x | M31: x | N31: x | O31: x | P31: x
... A48: Call of Duty | B48: PLATA | C48: PLATA | D48: x | E48: ORO | F48: PLATA | G48: x | H48: x | I48: x | J48: x | K48: x | L48: x | M48: x | N48: x | O48: x | P48: x
A100: v | B100: {=SUM(IF(B2:B99="v",1))} -> 10 | C100: {=SUM(IF(C2:C99="v",1))} -> 13 | D100: {=SUM(IF(D2:D99="v",1))} -> 0 | E100: {=SUM(IF(E2:E99="v",1))} -> 19 | F100: {=SUM(IF(F2:F99="v",1))} -> 13 | G100: {=SUM(IF(G2:G99="v",1))} -> 8 | H100: {=SUM(IF(H2:H99="v",1))} -> 15 | I100: {=SUM(IF(I2:I99="v",1))} -> 15 | ... P100: {=SUM(IF(P2:P99="v",1))} -> 0
A101: x | B101: {=SUM(IF(B2:B99="x",1))} -> 8 | C101: {=SUM(IF(C2:C99="x",1))} -> 4 | D101: {=SUM(IF(D2:D99="x",1))} -> 45 | E101: {=SUM(IF(E2:E99="x",1))} -> 3 | F101: {=SUM(IF(F2:F99="x",1))} -> 2 | G101: {=SUM(IF(G2:G99="x",1))} -> 35 | H101: {=SUM(IF(H2:H99="x",1))} -> 26 | I101: {=SUM(IF(I2:I99="x",1))} -> 25 | ... P101: {=SUM(IF(P2:P99="x",1))} -> 47
A102: Participaciones | B102: =B100+B103+B104+B105 -> 39 | C102: =C100+C103+C104+C105 -> 43 | D102: =D100+D103+D104+D105 -> 2 | E102: =E100+E103+E104+E105 -> 44 | F102: =F100+F103+F104+F105 -> 45 | G102: =G100+G103+G104+G105 -> 12 | H102: =H100+H103+H104+H105 -> 21 | I102: =I100+I103+I104+I105 -> 22 | ... P102: =P100+P103+P104+P105 -> 0
A103: BRONCE | B103: {=SUM(IF(B$2:B$99=$A103,1))} -> 5 | C103: {=SUM(IF(C$2:C$99=$A103,1))} -> 7 | D103: {=SUM(IF(D$2:D$99=$A103,1))} -> 1 | E103: {=SUM(IF(E$2:E$99=$A103,1))} -> 8 | F103: {=SUM(IF(F$2:F$99=$A103,1))} -> 6 | G103: {=SUM(IF(G$2:G$99=$A103,1))} -> 1 | H103: {=SUM(IF(H$2:H$99=$A103,1))} -> 1 | I103: {=SUM(IF(I$2:I$99=$A103,1))} -> 2 | ... P103: {=SUM(IF(P$2:P$99=$A103,1))} -> 0
A104: PLATA | B104: {=SUM(IF(B$2:B$99=$A104,1))} -> 10 | C104: {=SUM(IF(C$2:C$99=$A104,1))} -> 15 | D104: {=SUM(IF(D$2:D$99=$A104,1))} -> 1 | E104: {=SUM(IF(E$2:E$99=$A104,1))} -> 7 | F104: {=SUM(IF(F$2:F$99=$A104,1))} -> 13 | G104: {=SUM(IF(G$2:G$99=$A104,1))} -> 1 | H104: {=SUM(IF(H$2:H$99=$A104,1))} -> 3 | I104: {=SUM(IF(I$2:I$99=$A104,1))} -> 1 | ... P104: {=SUM(IF(P$2:P$99=$A104,1))} -> 0
A105: ORO | B105: {=SUM(IF(B$2:B$99=$A105,1))} -> 14 | C105: {=SUM(IF(C$2:C$99=$A105,1))} -> 8 | D105: {=SUM(IF(D$2:D$99=$A105,1))} -> 0 | E105: {=SUM(IF(E$2:E$99=$A105,1))} -> 10 | F105: {=SUM(IF(F$2:F$99=$A105,1))} -> 13 | G105: {=SUM(IF(G$2:G$99=$A105,1))} -> 2 | H105: {=SUM(IF(H$2:H$99=$A105,1))} -> 2 | I105: {=SUM(IF(I$2:I$99=$A105,1))} -> 4 | ... P105: {=SUM(IF(P$2:P$99=$A105,1))} -> 0
A106: Puntos | B106: =B103+B104*2+B105*3 -> 67 | C106: =C103+C104*2+C105*3 -> 61 | D106: =D103+D104*2+D105*3 -> 3 | E106: =E103+E104*2+E105*3 -> 52 | F106: =F103+F104*2+F105*3 -> 71 | G106: =G103+G104*2+G105*3 -> 9 | H106: =H103+H104*2+H105*3 -> 13 | I106: =I103+I104*2+I105*3 -> 16 | ... P106: =P103+P104*2+P105*3 -> 0
A107: Promedio | B107: =IF(B100+B103+B104+B105<>0,B106/(B100+B103+B104+B105),0) -> 1.7179487 | C107: =IF(C100+C103+C104+C105<>0,C106/(C100+C103+C104+C105),0) -> 1.4186047 | D107: =IF(D100+D103+D104+D105<>0,D106/(D100+D103+D104+D105),0) -> 1.5 | E107: =IF(E100+E103+E104+E105<>0,E106/(E100+E103+E104+E105),0) -> 1.1818182 | F107: =IF(F100+F103+F104+F105<>0,F106/(F100+F103+F104+F105),0) -> 1.5777778 | G107: =IF(G100+G103+G104+G105<>0,G106/(G100+G103+G104+G105),0) -> 0.75 | H107: =IF(H100+H103+H104+H105<>0,H106/(H100+H103+H104+H105),0) -> 0.61904762 | I107: =IF(I100+I103+I104+I105<>0,I106/(I100+I103+I104+I105),0) -> 0.72727273 | ... P107: =IF(P100+P103+P104+P105<>0,P106/(P100+P103+P104+P105),0) -> 0
...

Sheet 2014
A1: 2014 | B1: David | C1: Carlos | D1: Laura | E1: Jorge | F1: Sergio | G1: Poli | H1: Nuria | I1: Sara | J1: Dario | K1: Pedro | L1: Inés | M1: Chema | N1: Maite | O1: Anuncia | P1: Roberto
A2: Fútbol | B2: PLATA | C2: ORO | D2: x | E2: ORO | F2: ORO | G2: PLATA | H2: x | I2: x | J2: x | K2: x | L2: x | M2: x | N2: x | O2: x | P2: x
A3: Baloncesto | B3: ORO | C3: x | D3: PLATA | E3: x | F3: ORO | G3: PLATA | H3: x | I3: ORO | J3: x | K3: PLATA | L3: x | M3: x | N3: x | O3: x | P3: x
A4: Frontón | B4: x | C4: x | D4: x | E4: x | F4: ORO | G4: x | H4: x | I4: x | J4: x | K4: PLATA | L4: x | M4: x | N4: x | O4: x | P4: x
A5: COD | B5: PLATA | C5: x | D5: x | E5: x | F5: ORO | G5: x | H5: x | I5: x | J5: PLATA | K5: ORO | L5: x | M5: x | N5: x | O5: x | P5: x
A6: Cartas | B6: ORO | C6: x | D6: BRONCE | E6: x | F6: PLATA | G6: x | H6: x | I6: v | J6: v | K6: x | L6: x | M6: x | N6: x | O6: x | P6: x
A7: pueblo | B7: ORO | C7: x | D7: v | E7: x | F7: PLATA | G7: x | H7: x | I7: v | J7: BRONCE | K7: x | L7: x | M7: x | N7: x | O7: v | P7: x
A8: 7ymedio | B8: v | C8: x | D8: ORO | E8: x | F8: PLATA | G8: x | H8: x | I8: v | J8: BRONCE | K8: x | L8: x | M8: x | N8: x | O8: v | P8: x
A9: guiñar ojo | B9: v | C9: x | D9: PLATA | E9: x | F9: PLATA | G9: x | H9: x | I9: PLATA | J9: ORO | K9: x | L9: x | M9: x | N9: x | O9: v | P9: x
A10: poker | B10: v | C10: BRONCE | D10: PLATA | E10: v | F10: ORO | G10: x | H10: x | I10: x | J10: x | K10: x | L10: x | M10: x | N10: x | O10: x | P10: x
A11: catán | B11: ORO | C11: PLATA | D11: v | E11: BRONCE | F11: v | G11: ORO | H11: v | I11: v | J11: ORO | K11: x | L11: v | M11: x | N11: x | O11: x | P11: x
A12: lanzar avión | B12: BRONCE | C12: v | D12: v | E12: PLATA | F12: v | G12: x | H12: v | I12: v | J12: BRONCE | K12: x | L12: ORO | M12: v | N12: x | O12: x | P12: x
A13: lanzar pelota | B13: ORO | C13: v | D13: v | E13: v | F13: BRONCE | G13: v | H13: v | I13: v | J13: v | K13: x | L13: v | M13: PLATA | N13: x | O13: x | P13: x
... A19: Fútbol | B19: PLATA | C19: ORO | D19: x | E19: ORO | F19: PLATA | G19: x | H19: x | I19: ORO | J19: x | K19: x | L19: x | M19: x | N19: x | O19: x | P19: x
A20: -1 | B20: ORO | C20: v | D20: BRONCE | E20: PLATA | F20: v | G20: x | H20: x | I20: x | J20: x | K20: x | L20: x | M20: x | N20: x | O20: x | P20: x
A21: burro | B21: ORO | C21: v | D21: PLATA | E21: BRONCE | F21: v | G21: x | H21: x | I21: x | J21: v | K21: x | L21: x | M21: x | N21: x | O21: x | P21: x
A22: trenes | B22: ORO | C22: v | D22: BRONCE | E22: PLATA | F22: v | G22: ORO | H22: BRONCE | I22: PLATA | J22: ORO | K22: x | L22: x | M22: x | N22: x | O22: x | P22: x
A23: ajedrez | B23: PLATA | C23: PLATA | D23: x | E23: BRONCE | F23: ORO | G23: x | H23: v | I23: x | J23: x | K23: x | L23: x | M23: x | N23: x | O23: x | P23: x
A24: ps2 fifa | B24: ORO | C24: PLATA | D24: ORO | E24: PLATA | F24: ORO | G24: x | H24: x | I24: x | J24: PLATA | K24: x | L24: x | M24: x | N24: x | O24: x | P24: x
A25: quema | B25: ORO | C25: PLATA | D25: ORO | E25: ORO | F25: ORO | G25: PLATA | H25: PLATA | I25: ORO | J25: PLATA | K25: x | L25: x | M25: x | N25: x | O25: x | P25: x
A26: monstruos cartas | B26: x | C26: PLATA | D26: ORO | E26: v | F26: v | G26: x | H26: v | I26: PLATA | J26: x | K26: x | L26: x | M26: x | N26: x | O26: x | P26: x
A27: pañuelo | B27: PLATA | C27: ORO | D27: PLATA | E27: ORO | F27: PLATA | G27: x | H27: PLATA | I27: ORO | J27: x | K27: x | L27: x | M27: x | N27: x | O27: x | P27: x
A28: sillas | B28: x | C28: v | D28: x | E28: PLATA | F28: ORO | G28: x | H28: BRONCE | I28: v | J28: v | K28: x | L28: x | M28: x | N28: x | O28: x | P28: x
A29: petanca | B29: PLATA | C29: BRONCE | D29: ORO | E29: PLATA | F29: BRONCE | G29: PLATA | H29: ORO | I29: BRONCE | J29: PLATA | K29: x | L29: BRONCE | M29: BRONCE | N29: x | O29: x | P29: x
A30: ladron y policia | B30: v | C30: v | D30: ORO | E30: v | F30: v | G30: x | H30: ORO | I30: v | J30: v | K30: x | L30: x | M30: x | N30: x | O30: x | P30: x
A31: dixit | B31: v | C31: PLATA | D31: PLATA | E31: v | F31: v | G31: x | H31: ORO | I31: x | J31: v | K31: x | L31: x | M31: x | N31: x | O31: x | P31: x
A32: catán | B32: v | C32: v | D32: PLATA | E32: ORO | F32: v | G32: v | H32: PLATA | I32: v | J32: x | K32: x | L32: PLATA | M32: x | N32: x | O32: x | P32: x
... A45: trenes | B45: PLATA | C45: ORO | D45: v | E45: BRONCE | F45: v | G45: PLATA | H45: v | I45: BRONCE | J45: PLATA | K45: x | L45: x | M45: x | N45: x | O45: x | P45: x
A100: v | B100: {=SUM(IF(B2:B99="v",1))} -> 10 | C100: {=SUM(IF(C2:C99="v",1))} -> 14 | D100: {=SUM(IF(D2:D99="v",1))} -> 10 | E100: {=SUM(IF(E2:E99="v",1))} -> 11 | F100: {=SUM(IF(F2:F99="v",1))} -> 22 | G100: {=SUM(IF(G2:G99="v",1))} -> 5 | H100: {=SUM(IF(H2:H99="v",1))} -> 13 | I100: {=SUM(IF(I2:I99="v",1))} -> 18 | ... P100: {=SUM(IF(P2:P99="v",1))} -> 1
A101: x | B101: {=SUM(IF(B2:B99="x",1))} -> 7 | C101: {=SUM(IF(C2:C99="x",1))} -> 13 | D101: {=SUM(IF(D2:D99="x",1))} -> 10 | E101: {=SUM(IF(E2:E99="x",1))} -> 10 | F101: {=SUM(IF(F2:F99="x",1))} -> 3 | G101: {=SUM(IF(G2:G99="x",1))} -> 29 | H101: {=SUM(IF(H2:H99="x",1))} -> 17 | I101: {=SUM(IF(I2:I99="x",1))} -> 11 | ... P101: {=SUM(IF(P2:P99="x",1))} -> 43
A102: Participaciones | B102: =B100+B103+B104+B105 -> 37 | C102: =C100+C103+C104+C105 -> 31 | D102: =D100+D103+D104+D105 -> 34 | E102: =E100+E103+E104+E105 -> 34 | F102: =F100+F103+F104+F105 -> 41 | G102: =G100+G103+G104+G105 -> 15 | H102: =H100+H103+H104+H105 -> 27 | I102: =I100+I103+I104+I105 -> 33 | ... P102: =P100+P103+P104+P105 -> 1
A103: BRONCE | B103: {=SUM(IF(B$2:B$99=$A103,1))} -> 2 | C103: {=SUM(IF(C$2:C$99=$A103,1))} -> 4 | D103: {=SUM(IF(D$2:D$99=$A103,1))} -> 4 | E103: {=SUM(IF(E$2:E$99=$A103,1))} -> 7 | F103: {=SUM(IF(F$2:F$99=$A103,1))} -> 3 | G103: {=SUM(IF(G$2:G$99=$A103,1))} -> 1 | H103: {=SUM(IF(H$2:H$99=$A103,1))} -> 3 | I103: {=SUM(IF(I$2:I$99=$A103,1))} -> 3 | ... P103: {=SUM(IF(P$2:P$99=$A103,1))} -> 0
A104: PLATA | B104: {=SUM(IF(B$2:B$99=$A104,1))} -> 7 | C104: {=SUM(IF(C$2:C$99=$A104,1))} -> 7 | D104: {=SUM(IF(D$2:D$99=$A104,1))} -> 8 | E104: {=SUM(IF(E$2:E$99=$A104,1))} -> 7 | F104: {=SUM(IF(F$2:F$99=$A104,1))} -> 7 | G104: {=SUM(IF(G$2:G$99=$A104,1))} -> 6 | H104: {=SUM(IF(H$2:H$99=$A104,1))} -> 4 | I104: {=SUM(IF(I$2:I$99=$A104,1))} -> 5 | ... P104: {=SUM(IF(P$2:P$99=$A104,1))} -> 0
A105: ORO | B105: {=SUM(IF(B$2:B$99=$A105,1))} -> 18 | C105: {=SUM(IF(C$2:C$99=$A105,1))} -> 6 | D105: {=SUM(IF(D$2:D$99=$A105,1))} -> 12 | E105: {=SUM(IF(E$2:E$99=$A105,1))} -> 9 | F105: {=SUM(IF(F$2:F$99=$A105,1))} -> 9 | G105: {=SUM(IF(G$2:G$99=$A105,1))} -> 3 | H105: {=SUM(IF(H$2:H$99=$A105,1))} -> 7 | I105: {=SUM(IF(I$2:I$99=$A105,1))} -> 7 | ... P105: {=SUM(IF(P$2:P$99=$A105,1))} -> 0
A106: Puntos | B106: =B103+B104*2+B105*3 -> 70 | C106: =C103+C104*2+C105*3 -> 36 | D106: =D103+D104*2+D105*3 -> 56 | E106: =E103+E104*2+E105*3 -> 48 | F106: =F103+F104*2+F105*3 -> 44 | G106: =G103+G104*2+G105*3 -> 22 | H106: =H103+H104*2+H105*3 -> 32 | I106: =I103+I104*2+I105*3 -> 34 | ... P106: =P103+P104*2+P105*3 -> 0
A107: Promedio | B107: =IF(B100+B103+B104+B105<>0,B106/(B100+B103+B104+B105),0) -> 1.8918919 | C107: =IF(C100+C103+C104+C105<>0,C106/(C100+C103+C104+C105),0) -> 1.1612903 | D107: =IF(D100+D103+D104+D105<>0,D106/(D100+D103+D104+D105),0) -> 1.6470588 | E107: =IF(E100+E103+E104+E105<>0,E106/(E100+E103+E104+E105),0) -> 1.4117647 | F107: =IF(F100+F103+F104+F105<>0,F106/(F100+F103+F104+F105),0) -> 1.0731707 | G107: =IF(G100+G103+G104+G105<>0,G106/(G100+G103+G104+G105),0) -> 1.4666667 | H107: =IF(H100+H103+H104+H105<>0,H106/(H100+H103+H104+H105),0) -> 1.1851852 | I107: =IF(I100+I103+I104+I105<>0,I106/(I100+I103+I104+I105),0) -> 1.030303 | ... P107: =IF(P100+P103+P104+P105<>0,P106/(P100+P103+P104+P105),0) -> 0
A108: Check | B108: =B102+B101 -> 44 | C108: =C102+C101 -> 44 | D108: =D102+D101 -> 44 | E108: =E102+E101 -> 44 | F108: =F102+F101 -> 44 | G108: =G102+G101 -> 44 | H108: =H102+H101 -> 44 | I108: =I102+I101 -> 44 | ... P108: =P102+P101 -> 44
A110: Daypo | B110: =B106+G106+J106+I106 -> 153 | D110: Daypo adultos | E110: =B106+G106 -> 92 | G110: Daypo jóvenes | H110: =I106+J106 -> 61 | J110: participaciones | K110: =B102+G102+I102+J102 -> 115 | M110: promedio | N110: =B110/K110 -> 1.3304348
A111: Castrillo | B111: =C106+E106+H106+L106+M106 -> 134 | D111: Castrillo adulto | E111: =M106+L106 -> 18 | G111: Castrillo jóvenes | H111: =C106+E106+H106 -> 116 | J111: participaciones | K111: =C102+E102+H102+L102+M102 -> 111 | M111: promedio | N111: =B111/K111 -> 1.2072072
A112: Arroni Del Riego | B112: =D106+F106+K106+N106 -> 107 | D112: Del Riego adulto | E112: =K106+N106 -> 7 | G112: Del Riego jóvenes | H112: =D106+F106 -> 100 | J112: participaciones | K112: =D102+F102+K102+N102 -> 78 | M112: promedio | N112: =B112/K112 -> 1.3717949
...

Sheet 2015
A1: 2015 | B1: David | C1: Carlos | D1: Laura | E1: Jorge | F1: Sergio | G1: Poli | H1: Nuria | I1: Sara | J1: Dario | K1: Pedro | L1: Inés | M1: Chema | N1: Maite | O1: Anuncia | P1: Roberto
A2: Bádminton | B2: oro | C2: x | D2: plata | E2: x | F2: oro | K2: plata | M2: x | N2: x
A3: Fútbol | B3: oro | C3: x | E3: x | F3: plata | I3: oro | J3: oro | K3: plata | M3: x | N3: x
A4: -1 | B4: oro | C4: x | E4: x | F4: bronce | K4: plata | M4: x | N4: x
A5: call of duty | B5: plata | C5: x | E5: x | F5: oro | I5: plata | J5: oro | M5: x | N5: x
A6: Catán | C6: x | D6: oro | E6: x | F6: bronce | G6: plata | I6: bronce | M6: x | N6: x
A7: F1 | B7: oro | C7: x | E7: x | F7: plata | K7: bronce | M7: x | N7: x
A8: call of duty | B8: plata | C8: x | E8: x | F8: oro | J8: oro | K8: plata | M8: x | N8: x
A9: petanca | B9: plata | C9: x | E9: x | F9: bronce | H9: oro | I9: oro | J9: plata | M9: x | N9: x | O9: bronce
A10: buzz niños | C10: x | D10: oro | E10: x | F10: plata | H10: bronce | J10: bronce | M10: x | N10: x
A11: -1 | B11: plata | C11: x | D11: bronce | E11: x | F11: oro | M11: x | N11: x
A12: burro | B12: oro | C12: x | D12: plata | E12: x | F12: bronce | M12: x | N12: x
A13: buzz | B13: oro | C13: x | D13: bronce | E13: x | G13: plata | M13: x | N13: x
A14: interferencias | B14: plata | C14: x | E14: x | H14: oro | J14: oro | L14: bronce | M14: x | N14: x
A15: sumas | B15: oro | C15: x | E15: x | F15: bronce | M15: x | N15: x | P15: plata
A16: criquet | B16: plata | C16: x | E16: x | G16: bronce | J16: oro | M16: x | N16: x
A17: buzz niños | B17: bronce | C17: x | D17: oro | E17: x | F17: plata | M17: x | N17: x
A18: parchis | B18: plata | C18: x | D18: oro | E18: x | F18: oro | J18: plata | M18: x | N18: x
A19: mario party | C19: x | D19: bronce | E19: x | F19: plata | J19: oro | M19: x | N19: x
A20: pringels | B20: bronce | C20: x | E20: x | G20: plata | I20: oro | M20: x | N20: x
A21: interferencias | B21: plata | C21: x | D21: oro | E21: x | F21: bronce | H21: oro | J21: bronce | M21: x | N21: x
A22: fronton | B22: oro | C22: x | E22: x | G22: bronce | I22: plata | M22: x | N22: x
A23: call of duty | B23: plata | C23: x | E23: x | F23: oro | J23: plata | M23: x | N23: x
A24: ginkana | B24: oro | C24: x | E24: x | F24: plata | G24: plata | H24: plata | I24: oro | J24: oro | M24: x | N24: x
A25: sillas | C25: x | E25: x | F25: oro | I25: plata | L25: bronce | M25: x | N25: x
A26: campos medios | B26: oro | C26: x | E26: x | F26: plata | G26: oro | H26: plata | I26: oro | J26: plata | L26: plata | M26: x | N26: x
A27: sillas junior | C27: x | E27: x | F27: oro | H27: plata | I27: bronce | M27: x | N27: x
A28: trenes | B28: plata | C28: x | D28: bronce | E28: x | F28: oro | H28: bronce | M28: x | N28: x
A29: parchis | C29: x | D29: oro | E29: x | F29: bronce | H29: oro | I29: plata | J29: bronce | M29: x | N29: x
A30: cuentos | C30: x | D30: bronce | E30: x | F30: plata | I30: bronce | J30: bronce | L30: oro | M30: x | N30: x
A31: 7 y media | B31: plata | C31: x | D31: bronce | E31: x | F31: oro | H31: plata | I31: oro | J31: oro | L31: plata | M31: x | N31: x
A32: burro | B32: plata | C32: x | D32: bronce | E32: x | G32: bronce | H32: bronce | J32: oro | M32: x | N32: x
A33: Piscina: rapidez nadar | B33: oro | C33: x | D33: bronce | E33: x | I33: plata | M33: x | N33: x
A34: Piscina: nadar sin respirar | B34: oro | C34: x | D34: plata | E34: x | I34: bronce | M34: x | N34: x
A35: Piscina: impulso | B35: oro | C35: x | D35: plata | E35: x | I35: bronce | M35: x | N35: x
A36: Piscina: pino | C36: x | D36: oro | E36: x | F36: plata | I36: bronce | M36: x | N36: x
A37: trenes | B37: bronce | C37: x | D37: plata | E37: x | F37: oro | J37: oro | M37: x | N37: x
A38: volley | B38: plata | C38: x | D38: oro | E38: x | F38: oro | H38: plata | I38: plata | J38: oro | M38: x | N38: x
A39: -1 | B39: oro | C39: x | E39: x | F39: plata | M39: x | N39: x
A40: dardos | B40: oro | C40: x | E40: x | F40: plata | J40: bronce | M40: x | N40: x
...

Sheet 2016
A1: 2016 | B1: David | C1: Carlos | D1: Laura | E1: Jorge | F1: Sergio | G1: Poli | H1: Nuria | I1: Sara | J1: Dario | K1: Pedro | L1: Inés | M1: Chema | N1: Maite | O1: Anuncia | P1: Roberto | Q1: Hana
A2: Catán | B2: ORO | C2: x | D2: x | E2: x | F2: x | G2: BRONCE | H2: x | I2: PLATA | J2: BRONCE | K2: x | L2: x | M2: x | N2: x | O2: PLATA | P2: x | Q2: x | R2: Catán
A3: Call of Duty | B3: PLATA | C3: x | D3: x | E3: x | F3: ORO | G3: x | H3: x | I3: PLATA | J3: ORO | K3: x | L3: x | M3: x | N3: x | O3: x | P3: x | Q3: x | R3: Call of Duty
A4: Call of Duty | B4: x | C4: PLATA | D4: x | E4: ORO | F4: ORO | G4: x | H4: x | I4: x | J4: BRONCE | K4: x | L4: x | M4: x | N4: x | O4: x | P4: x | Q4: x | R4: Call of Duty
A5: Fútbol | B5: ORO | C5: ORO | D5: x | E5: ORO | F5: PLATA | G5: x | H5: x | I5: PLATA | J5: x | K5: PLATA | L5: x | M5: x | N5: x | O5: x | P5: x | Q5: x | R5: Fútbol
A6: -1 | B6: BRONCE | C6: v | D6: x | E6: v | F6: PLATA | G6: x | H6: x | I6: v | J6: x | K6: ORO | L6: x | M6: x | N6: x | O6: x | P6: x | Q6: x | R6: -1
A7: Burro | B7: ORO | C7: v | D7: x | E7: BRONCE | F7: PLATA | G7: x | H7: x | I7: v | J7: x | K7: x | L7: x | M7: x | N7: x | O7: x | P7: x | Q7: x | R7: Burro
A8: Gymkana | B8: ORO | C8: ORO | D8: x | E8: v | F8: v | G8: ORO | H8: x | I8: ORO | J8: v | K8: v | L8: x | M8: x | N8: x | O8: x | P8: x | Q8: x | R8: Gymkana
A9: Interferencias | B9: x | C9: v | D9: v | E9: v | F9: ORO | G9: x | H9: v | I9: v | J9: ORO | K9: v | L9: x | M9: x | N9: x | O9: x | P9: x | Q9: v | R9: Interferencias
A10: Catán | B10: ORO | C10: v | D10: v | E10: v | F10: BRONCE | G10: x | H10: PLATA | I10: PLATA | J10: BRONCE | K10: x | L10: x | M10: x | N10: x | O10: x | P10: x | Q10: v | R10: Catán
A11: Perdigones | B11: x | C11: v | D11: ORO | E11: ORO | F11: PLATA | G11: x | H11: x | I11: x | J11: PLATA | K11: ORO | L11: x | M11: x | N11: x | O11: x | P11: x | Q11: x | R11: Perdigones
A12: Frontón | B12: ORO | C12: v | D12: v | E12: BRONCE | F12: v | G12: PLATA | H12: v | I12: v | J12: v | K12: v | L12: x | M12: x | N12: x | O12: x | P12: x | Q12: v | R12: Frontón
A13: Frontón | B13: ORO | C13: v | D13: v | E13: BRONCE | F13: v | G13: v | H13: v | I13: v | J13: v | K13: PLATA | L13: x | M13: x | N13: x | O13: x | P13: x | Q13: v | R13: Frontón
A14: Lanzar avión | B14: BRONCE | C14: v | D14: v | E14: v | F14: v | G14: v | H14: v | I14: ORO | J14: v | K14: PLATA | L14: x | M14: x | N14: x | O14: v | P14: x | Q14: v | R14: Lanzar avión
A15: Lanzar pelota (tenis) | B15: PLATA | C15: v | D15: v | E15: v | F15: BRONCE | G15: v | H15: v | I15: v | J15: v | K15: v | L15: x | M15: x | N15: x | O15: v | P15: x | Q15: ORO | R15: Lanzar pelota (tenis)
A16: Lanzar pelotas (longitud) | B16: PLATA | C16: v | D16: v | E16: v | F16: ORO | G16: v | H16: v | I16: v | J16: v | K16: BRONCE | L16: x | M16: x | N16: x | O16: v | P16: x | Q16: v | R16: Lanzar pelotas (longitud)
A17: Petanca | B17: ORO | C17: v | D17: BRONCE | E17: v | F17: PLATA | G17: v | H17: v | I17: v | J17: PLATA | K17: BRONCE | L17: x | M17: x | N17: x | O17: ORO | P17: x | Q17: v | R17: Petanca
A18: Pañuelo | B18: v | C18: ORO | D18: x | E18: ORO | F18: v | G18: ORO | H18: ORO | I18: ORO | J18: v | K18: v | L18: x | M18: x | N18: x | O18: x | P18: x | Q18: v | R18: Pañuelo
... A40: Catán | B40: ORO | C40: x | D40: x | E40: PLATA | F40: BRONCE | G40: v | H40: BRONCE | I40: v | J40: BRONCE | K40: x | L40: BRONCE | M40: x | N40: x | O40: x | P40: x | Q40: x | R40: Catán
A41: -1 | B41: ORO | C41: x | D41: x | E41: BRONCE | F41: PLATA | G41: x | H41: x | I41: v | J41: x | K41: x | L41: x | M41: x | N41: x | O41: x | P41: x | Q41: x | R41: -1
A42: Burro | B42: PLATA | C42: x | D42: x | E42: ORO | F42: BRONCE | G42: x | H42: x | I42: v | J42: x | K42: x | L42: x | M42: x | N42: x | O42: x | P42: x | Q42: x | R42: Burro
A43: Baloncesto | B43: ORO | C43: x | D43: x | E43: PLATA | F43: PLATA | G43: x | H43: x | I43: ORO | J43: PLATA | K43: x | L43: x | M43: x | N43: x | O43: x | P43: x | Q43: x | R43: Baloncesto
A44: Porra | B44: v | C44: x | D44: x | E44: v | F44: BRONCE | G44: v | H44: ORO | I44: v | J44: v | K44: x | L44: x | M44: x | N44: x | O44: PLATA | P44: x | Q44: x | R44: Porra
A45: Fútbol | B45: ORO | C45: x | D45: x | E45: PLATA | F45: PLATA | G45: x | H45: x | I45: ORO | J45: PLATA | K45: x | L45: x | M45: x | N45: x | O45: x | P45: x | Q45: x | R45: Fútbol
A46: -1 | B46: BRONCE | C46: x | D46: x | E46: ORO | F46: PLATA | G46: x | H46: x | I46: x | J46: x | K46: x | L46: v | M46: x | N46: x | O46: x | P46: x | Q46: x | R46: -1
A47: Volleyball | B47: PLATA | C47: x | D47: x | E47: ORO | F47: ORO | G47: x | H47: x | I47: x | J47: x | K47: x | L47: x | M47: x | N47: x | O47: x | P47: x | Q47: x | R47: Volleyball
A48: Incógnito | B48: PLATA | C48: x | D48: x | E48: ORO | F48: ORO | G48: x | H48: x | I48: x | J48: PLATA | K48: x | L48: x | M48: x | N48: x | O48: x | P48: x | Q48: x | R48: Incógnito
A49: Fifa | B49: PLATA | C49: x | D49: x | E49: BRONCE | F49: ORO | G49: x | H49: x | I49: x | J49: v | K49: x | L49: x | M49: x | N49: x | O49: x | P49: x | Q49: x | R49: Fifa
A50: Frontón | B50: ORO | C50: x | D50: x | E50: PLATA | F50: BRONCE | G50: PLATA | H50: v | I50: BRONCE | J50: v | K50: x | L50: v | M50: x | N50: x | O50: x | P50: x | Q50: x | R50: Frontón
A51: Frontón | B51: ORO | C51: x | D51: x | E51: v | F51: v | G51: v | H51: v | I51: v | J51: v | K51: x | L51: v | M51: x | N51: x | O51: x | P51: x | Q51: x | R51: Frontón
A52: Catán | B52: PLATA | C52: x | D52: x | E52: v | F52: ORO | G52: PLATA | H52: BRONCE | I52: PLATA | J52: x | K52: x | L52: v | M52: x | N52: x | O52: x | P52: x | Q52: x | R52: Catán
A53: Frontón | B53: x | C53: x | D53: x | E53: x | F53: x | G53: PLATA | H53: x | I53: ORO | J53: v | K53: x | L53: v | M53: x | N53: x | O53: x | P53: x | Q53: x | R53: Frontón
A54: -1 | B54: ORO | C54: x | D54: x | E54: BRONCE | F54: PLATA | G54: x | H54: x | I54: x | J54: v | K54: x | L54: x | M54: x | N54: x | O54: x | P54: x | Q54: x | R54: -1
A55: -1 | B55: ORO | C55: x | D55: x | E55: BRONCE | F55: PLATA | G55: x | H55: x | I55: x | J55: x | K55: x | L55: x | M55: x | N55: x | O55: x | P55: x | Q55: x | R55: -1
A56: Partido | B56: ORO | C56: x | D56: x | E56: PLATA | F56: PLATA | G56: x | H56: x | I56: x | J56: x | K56: x | L56: x | M56: x | N56: x | O56: x | P56: x | Q56: x | R56: Partido
A57: Burro | B57: BRONCE | C57: x | D57: x | E57: PLATA | F57: ORO | G57: x | H57: x | I57: x | J57: x | K57: x | L57: x | M57: x | N57: x | O57: x | P57: x | Q57: x | R57: Burro
A58: Frontón | B58: ORO | C58: x | D58: x | E58: PLATA | F58: BRONCE | G58: x | H58: x | I58: x | J58: x | K58: x | L58: x | M58: x | N58: x | O58: x | P58: x | Q58: x | R58: Frontón
A59: Frontón | B59: ORO | C59: x | D59: x | E59: PLATA | F59: BRONCE | G59: x | H59: x | I59: x | J59: x | K59: x | L59: x | M59: x | N59: x | O59: x | P59: x | Q59: x | R59: Frontón
A60: Dobles | B60: PLATA | C60: x | D60: x | E60: ORO | F60: ORO | G60: x | H60: x | I60: PLATA | J60: x | K60: x | L60: x | M60: x | N60: x | O60: x | P60: x | Q60: x | R60: Dobles
A61: Incógnito | B61: PLATA | C61: x | D61: x | E61: ORO | F61: ORO | G61: x | H61: x | I61: x | J61: PLATA | K61: x | L61: x | M61: x | N61: x | O61: x | P61: x | Q61: x | R61: Incógnito
...

Sheet 2017
A1: 2017 | B1: David | C1: Carlos | D1: Laura | E1: Jorge | F1: Sergio | G1: Poli | H1: Nuria | I1: Sara | J1: Dario | K1: Pedro | L1: Inés | M1: Chema | N1: Maite | O1: Anuncia | P1: Roberto | Q1: Hana
A2: Mario Kart | B2: x | C2: x | D2: x | E2: ORO | F2: ORO | G2: x | H2: PLATA | I2: PLATA | J2: x | K2: x | L2: x | M2: x | N2: x | O2: x | P2: x | Q2: x
A3: Mario Kart | B3: x | C3: x | D3: x | E3: ORO | F3: ORO | G3: x | H3: PLATA | I3: PLATA | J3: x | K3: x | L3: x | M3: x | N3: x | O3: x | P3: x | Q3: x
A4: Mario Kart | B4: x | C4: x | D4: x | E4: ORO | F4: PLATA | G4: x | H4: BRONCE | I4: x | J4: x | K4: x | L4: x | M4: x | N4: x | O4: x | P4: x | Q4: x
A5: Juego mentiras | B5: v | C5: x | D5: x | E5: PLATA | F5: ORO | G5: x | H5: v | I5: BRONCE | J5: v | K5: ORO | L5: x | M5: x | N5: x | O5: x | P5: x | Q5: x
A6: Frontón | B6: v | C6: x | D6: x | E6: BRONCE | F6: ORO | G6: v | H6: v | I6: v | J6: v | K6: PLATA | L6: x | M6: x | N6: x | O6: x | P6: x | Q6: x
A7: Fronton equipos | B7: PLATA | C7: x | D7: x | E7: ORO | F7: ORO | G7: BRONCE | H7: BRONCE | I7: BRONCE | J7: PLATA | K7: BRONCE | L7: x | M7: x | N7: x | O7: x | P7: x | Q7: x
A8: Baloncesto | B8: ORO | C8: x | D8: x | E8: PLATA | F8: ORO | G8: x | H8: x | I8: PLATA | J8: ORO | K8: PLATA | L8: x | M8: x | N8: x | O8: x | P8: x | Q8: x
A9: -1 | B9: PLATA | C9: x | D9: x | E9: BRONCE | F9: BRONCE | G9: x | H9: v | I9: ORO | J9: x | K9: v | L9: x | M9: x | N9: x | O9: x | P9: x | Q9: x
A10: Interferencias | B10: v | C10: x | D10: x | E10: v | F10: v | G10: x | H10: v | I10: v | J10: ORO | K10: ORO | L10: x | M10: x | N10: x | O10: v | P10: x | Q10: x
A11: Lanzamiento de pelota | B11: ORO | C11: x | D11: x | E11: x | F11: PLATA | G11: x | H11: x | I11: v | J11: v | K11: BRONCE | L11: x | M11: x | N11: x | O11: x | P11: x | Q11: x
A12: Pistas | B12: v | C12: x | D12: x | E12: v | F12: ORO | G12: v | H12: ORO | I12: v | J12: ORO | K12: v | L12: v | M12: x | N12: x | O12: x | P12: x | Q12: x
A13: Encestar terraza | B13: x | C13: x | D13: x | E13: x | F13: x | G13: x | H13: v | I13: PLATA | J13: ORO | K13: x | L13: x | M13: x | N13: x | O13: x | P13: x | Q13: x
A14: Trenes | B14: ORO | C14: x | D14: x | E14: v | F14: BRONCE | G14: x | H14: PLATA | I14: ORO | J14: x | K14: v | L14: PLATA | M14: x | N14: x | O14: x | P14: x | Q14: x
A15: Petanca | B15: ORO | C15: x | D15: x | E15: PLATA | F15: ORO | G15: x | H15: v | I15: v | J15: ORO | K15: x | L15: PLATA | M15: x | N15: x | O15: ORO | P15: x | Q15: x
A16: Dardos | B16: PLATA | C16: x | D16: x | E16: BRONCE | F16: v | G16: x | H16: x | I16: x | J16: v | K16: ORO | L16: v | M16: x | N16: x | O16: x | P16: x | Q16: x
A17: Aviones | B17: BRONCE | C17: x | D17: x | E17: BRONCE | F17: v | G17: x | H17: v | I17: PLATA | J17: v | K17: ORO | L17: v | M17: x | N17: x | O17: x | P17: x | Q17: x
A18: Fútbol | B18: PLATA | C18: x | D18: x | E18: ORO | F18: ORO | G18: x | H18: x | I18: PLATA | J18: x | K18: x | L18: x | M18: x | N18: x | O18: x | P18: x | Q18: x
A19: Mentiras | B19: x | C19: x | D19: x | E19: ORO | F19: ORO | G19: x | H19: x | I19: x | J19: PLATA | K19: x | L19: x | M19: x | N19: x | O19: x | P19: x | Q19: x
A20: Biad taxi | B20: ORO | C20: x | D20: x | E20: BRONCE | F20: v | G20: x | H20: x | I20: x | J20: x | K20: x | L20: x | M20: x | N20: x | O20: PLATA | P20: x | Q20: x
A21: Catán | B21: BRONCE | C21: x | D21: x | E21: BRONCE | F21: PLATA | G21: x | H21: v | I21: ORO | J21: v | K21: x | L21: x | M21: x | N21: x | O21: x | P21: x | Q21: x
... A24: Frontón | B24: ORO | C24: x | D24: x | E24: PLATA | F24: BRONCE | G24: x | H24: x | I24: v | J24: x | K24: x | L24: x | M24: x | N24: x | O24: x | P24: x | Q24: x
A25: -1 | B25: PLATA | C25: x | D25: x | E25: v | F25: BRONCE | G25: x | H25: v | I25: ORO | J25: x | K25: x | L25: x | M25: x | N25: x | O25: x | P25: x | Q25: x
A26: Frontón | B26: PLATA | C26: x | D26: x | E26: v | F26: BRONCE | G26: v | H26: v | I26: ORO | J26: v | K26: x | L26: v | M26: x | N26: x | O26: x | P26: x | Q26: x
A27: Call of Duty | B27: x | C27: x | D27: x | E27: ORO | F27: PLATA | G27: x | H27: x | I27: v | J27: BRONCE | K27: x | L27: x | M27: x | N27: x | O27: x | P27: x | Q27: x
A28: Mario Kart | B28: BRONCE | C28: x | D28: x | E28: ORO | F28: PLATA | G28: x | H28: x | I28: x | J28: v | K28: x | L28: x | M28: x | N28: x | O28: x | P28: x | Q28: x
A29: Asesino | B29: BRONCE | C29: x | D29: x | E29: x | F29: v | G29: x | H29: ORO | I29: PLATA | J29: v | K29: x | L29: x | M29: x | N29: x | O29: v | P29: x | Q29: x
A100: v | B100: {=SUM(IF(B2:B99="v",1))} -> 5 | C100: {=SUM(IF(C2:C99="v",1))} -> 0 | D100: {=SUM(IF(D2:D99="v",1))} -> 0 | E100: {=SUM(IF(E2:E99="v",1))} -> 6 | F100: {=SUM(IF(F2:F99="v",1))} -> 5 | G100: {=SUM(IF(G2:G99="v",1))} -> 3 | H100: {=SUM(IF(H2:H99="v",1))} -> 11 | I100: {=SUM(IF(I2:I99="v",1))} -> 7 | ... Q100: {=SUM(IF(Q2:Q99="v",1))} -> 0 | R100: v
